2018-12-04 22:53:23,003 ERROR: Exception on /favicon.ico [GET] [in /home/max/Projects/flask-blog-two/venv/lib/python3.7/site-packages/flask/app.py:1761]
Traceback (most recent call last):
  File "/home/max/Projects/flask-blog-two/venv/lib/python3.7/site-packages/sqlalchemy/engine/base.py", line 1193, in _execute_context
    context)
  File "/home/max/Projects/flask-blog-two/venv/lib/python3.7/site-packages/sqlalchemy/engine/default.py", line 509, in do_execute
    cursor.execute(statement, parameters)
sqlite3.OperationalError: no such table: user

The above exception was the direct cause of the following exception:

Traceback (most recent call last):
  File "/home/max/Projects/flask-blog-two/venv/lib/python3.7/site-packages/flask/app.py", line 2292, in wsgi_app
    response = self.full_dispatch_request()
  File "/home/max/Projects/flask-blog-two/venv/lib/python3.7/site-packages/flask/app.py", line 1815, in full_dispatch_request
    rv = self.handle_user_exception(e)
  File "/home/max/Projects/flask-blog-two/venv/lib/python3.7/site-packages/flask/app.py", line 1718, in handle_user_exception
    reraise(exc_type, exc_value, tb)
  File "/home/max/Projects/flask-blog-two/venv/lib/python3.7/site-packages/flask/_compat.py", line 35, in reraise
    raise value
  File "/home/max/Projects/flask-blog-two/venv/lib/python3.7/site-packages/flask/app.py", line 1811, in full_dispatch_request
    rv = self.preprocess_request()
  File "/home/max/Projects/flask-blog-two/venv/lib/python3.7/site-packages/flask/app.py", line 2087, in preprocess_request
    rv = func()
  File "/home/max/Projects/flask-blog-two/app/routes.py", line 12, in before_request
    if current_user.is_authenticated:
  File "/home/max/Projects/flask-blog-two/venv/lib/python3.7/site-packages/werkzeug/local.py", line 347, in __getattr__
    return getattr(self._get_current_object(), name)
  File "/home/max/Projects/flask-blog-two/venv/lib/python3.7/site-packages/werkzeug/local.py", line 306, in _get_current_object
    return self.__local()
  File "/home/max/Projects/flask-blog-two/venv/lib/python3.7/site-packages/flask_login/utils.py", line 26, in <lambda>
    current_user = LocalProxy(lambda: _get_user())
  File "/home/max/Projects/flask-blog-two/venv/lib/python3.7/site-packages/flask_login/utils.py", line 335, in _get_user
    current_app.login_manager._load_user()
  File "/home/max/Projects/flask-blog-two/venv/lib/python3.7/site-packages/flask_login/login_manager.py", line 359, in _load_user
    return self.reload_user()
  File "/home/max/Projects/flask-blog-two/venv/lib/python3.7/site-packages/flask_login/login_manager.py", line 321, in reload_user
    user = self.user_callback(user_id)
  File "/home/max/Projects/flask-blog-two/app/models.py", line 63, in load_user
    return User.query.get(int(id))
  File "/home/max/Projects/flask-blog-two/venv/lib/python3.7/site-packages/sqlalchemy/orm/query.py", line 924, in get
    ident, loading.load_on_pk_identity)
  File "/home/max/Projects/flask-blog-two/venv/lib/python3.7/site-packages/sqlalchemy/orm/query.py", line 1007, in _get_impl
    return db_load_fn(self, primary_key_identity)
  File "/home/max/Projects/flask-blog-two/venv/lib/python3.7/site-packages/sqlalchemy/orm/loading.py", line 250, in load_on_pk_identity
    return q.one()
  File "/home/max/Projects/flask-blog-two/venv/lib/python3.7/site-packages/sqlalchemy/orm/query.py", line 2954, in one
    ret = self.one_or_none()
  File "/home/max/Projects/flask-blog-two/venv/lib/python3.7/site-packages/sqlalchemy/orm/query.py", line 2924, in one_or_none
    ret = list(self)
  File "/home/max/Projects/flask-blog-two/venv/lib/python3.7/site-packages/sqlalchemy/orm/query.py", line 2995, in __iter__
    return self._execute_and_instances(context)
  File "/home/max/Projects/flask-blog-two/venv/lib/python3.7/site-packages/sqlalchemy/orm/query.py", line 3018, in _execute_and_instances
    result = conn.execute(querycontext.statement, self._params)
  File "/home/max/Projects/flask-blog-two/venv/lib/python3.7/site-packages/sqlalchemy/engine/base.py", line 948, in execute
    return meth(self, multiparams, params)
  File "/home/max/Projects/flask-blog-two/venv/lib/python3.7/site-packages/sqlalchemy/sql/elements.py", line 269, in _execute_on_connection
    return connection._execute_clauseelement(self, multiparams, params)
  File "/home/max/Projects/flask-blog-two/venv/lib/python3.7/site-packages/sqlalchemy/engine/base.py", line 1060, in _execute_clauseelement
    compiled_sql, distilled_params
  File "/home/max/Projects/flask-blog-two/venv/lib/python3.7/site-packages/sqlalchemy/engine/base.py", line 1200, in _execute_context
    context)
  File "/home/max/Projects/flask-blog-two/venv/lib/python3.7/site-packages/sqlalchemy/engine/base.py", line 1413, in _handle_dbapi_exception
    exc_info
  File "/home/max/Projects/flask-blog-two/venv/lib/python3.7/site-packages/sqlalchemy/util/compat.py", line 265, in raise_from_cause
    reraise(type(exception), exception, tb=exc_tb, cause=cause)
  File "/home/max/Projects/flask-blog-two/venv/lib/python3.7/site-packages/sqlalchemy/util/compat.py", line 248, in reraise
    raise value.with_traceback(tb)
  File "/home/max/Projects/flask-blog-two/venv/lib/python3.7/site-packages/sqlalchemy/engine/base.py", line 1193, in _execute_context
    context)
  File "/home/max/Projects/flask-blog-two/venv/lib/python3.7/site-packages/sqlalchemy/engine/default.py", line 509, in do_execute
    cursor.execute(statement, parameters)
sqlalchemy.exc.OperationalError: (sqlite3.OperationalError) no such table: user [SQL: 'SELECT user.id AS user_id, user.username AS user_username, user.email AS user_email, user.password_hash AS user_password_hash, user.about_me AS user_about_me, user.last_seen AS user_last_seen \nFROM user \nWHERE user.id = ?'] [parameters: (1,)] (Background on this error at: http://sqlalche.me/e/e3q8)
2018-12-04 22:53:37,206 INFO: Blog startup [in /home/max/Projects/flask-blog-two/app/__init__.py:45]
2018-12-04 22:53:46,232 INFO: Blog startup [in /home/max/Projects/flask-blog-two/app/__init__.py:45]
2018-12-04 22:53:58,500 INFO: Blog startup [in /home/max/Projects/flask-blog-two/app/__init__.py:45]
2018-12-04 22:54:16,898 INFO: Blog startup [in /home/max/Projects/flask-blog-two/app/__init__.py:45]
2018-12-04 23:00:24,301 INFO: Blog startup [in /home/max/Projects/flask-blog-two/app/__init__.py:45]
2018-12-04 23:00:40,041 INFO: Blog startup [in /home/max/Projects/flask-blog-two/app/__init__.py:45]
2018-12-04 23:00:44,206 ERROR: Exception on / [GET] [in /home/max/Projects/flask-blog-two/venv/lib/python3.7/site-packages/flask/app.py:1761]
Traceback (most recent call last):
  File "/home/max/Projects/flask-blog-two/venv/lib/python3.7/site-packages/flask/app.py", line 2292, in wsgi_app
    response = self.full_dispatch_request()
  File "/home/max/Projects/flask-blog-two/venv/lib/python3.7/site-packages/flask/app.py", line 1815, in full_dispatch_request
    rv = self.handle_user_exception(e)
  File "/home/max/Projects/flask-blog-two/venv/lib/python3.7/site-packages/flask/app.py", line 1718, in handle_user_exception
    reraise(exc_type, exc_value, tb)
  File "/home/max/Projects/flask-blog-two/venv/lib/python3.7/site-packages/flask/_compat.py", line 35, in reraise
    raise value
  File "/home/max/Projects/flask-blog-two/venv/lib/python3.7/site-packages/flask/app.py", line 1813, in full_dispatch_request
    rv = self.dispatch_request()
  File "/home/max/Projects/flask-blog-two/venv/lib/python3.7/site-packages/flask/app.py", line 1799, in dispatch_request
    return self.view_functions[rule.endpoint](**req.view_args)
  File "/home/max/Projects/flask-blog-two/venv/lib/python3.7/site-packages/flask_login/utils.py", line 261, in decorated_view
    return func(*args, **kwargs)
  File "/home/max/Projects/flask-blog-two/app/routes.py", line 31, in index
    return render_template('index.html', title='Home', posts=posts)
  File "/home/max/Projects/flask-blog-two/venv/lib/python3.7/site-packages/flask/templating.py", line 135, in render_template
    context, ctx.app)
  File "/home/max/Projects/flask-blog-two/venv/lib/python3.7/site-packages/flask/templating.py", line 117, in _render
    rv = template.render(context)
  File "/home/max/Projects/flask-blog-two/venv/lib/python3.7/site-packages/jinja2/asyncsupport.py", line 76, in render
    return original_render(self, *args, **kwargs)
  File "/home/max/Projects/flask-blog-two/venv/lib/python3.7/site-packages/jinja2/environment.py", line 1008, in render
    return self.environment.handle_exception(exc_info, True)
  File "/home/max/Projects/flask-blog-two/venv/lib/python3.7/site-packages/jinja2/environment.py", line 780, in handle_exception
    reraise(exc_type, exc_value, tb)
  File "/home/max/Projects/flask-blog-two/venv/lib/python3.7/site-packages/jinja2/_compat.py", line 37, in reraise
    raise value.with_traceback(tb)
  File "/home/max/Projects/flask-blog-two/app/templates/index.html", line 1, in top-level template code
    {% extends "base.html" %}
  File "/home/max/Projects/flask-blog-two/app/templates/base.html", line 34, in top-level template code
    {% block content %}{% endblock %}
  File "/home/max/Projects/flask-blog-two/app/templates/index.html", line 7, in block "content"
    {{ form.hidden_tag() }}
  File "/home/max/Projects/flask-blog-two/venv/lib/python3.7/site-packages/jinja2/environment.py", line 430, in getattr
    return getattr(obj, attribute)
jinja2.exceptions.UndefinedError: 'form' is undefined
2018-12-04 23:08:09,695 INFO: Blog startup [in /home/max/Projects/flask-blog-two/app/__init__.py:45]
